Workbook

Sheet README
C1: FAMILY JOINT FINANCES — 30-YEAR PROJECTION, 2026 TO 2055 (version 2)
C3: Rebuilt with workplace and employer pension contributions, the 8%-to-2% return glidepath, the 19-year mortgage, maternity leave, self-sizing Junior ISAs, and contributions that are DERIVED from what is actually affordable rather than assumed. Every number is a live formula.
C5: START HERE
C6: 1. Analysis — the written answers.
C7: 2. Analysis_DM_Exit — when DM can stop, base case: three rungs, and a year-by-year sweep behind them.
C8: 3. Analysis_Exit_3rd — the same question with a third child.
C9: 4. Assumptions — every input. Blue cells are yours to change; yellow ones matter most.
C11: THE SHEETS
C12: README — This page.
C13: Analysis — The written analysis and recommendations.
C14: Assumptions — Every input: inflation, salaries, base salaries, pension percentages, balances, expenses, children's dates, tax parameters, maternity leave, and the definitions of the three tests.
C15: Tax_Bands — UK tax thresholds and allowances year by year — frozen in cash terms to 2030/31, then uprated with inflation.
... C62: This is a planning model, not regulated financial advice. With pensions on track to pass £12m, take advice on the lump sum allowance (£268,275 each) and on inheritance tax before acting on any of it.

Sheet Analysis
C1: ANALYSIS — WHEN CAN DM STOP WORKING?
C3: THE HEADLINE: THE ANSWER HAS MOVED A LONG WAY, AND IN YOUR FAVOUR
C4: On the numbers you have now given, DM does not have a date so much as a choice. Even with DM earning nothing at all from the business, the household is solvent all the way to retirement if he stops at the end of THIS year.
C5: Three things moved it. (1) A correction: version 1 treated a £1 gross SIPP contribution as £1 of cash leaving the household, when relief at source means it costs 80p — that alone was worth about £24,000 a year. (2) Employer pension contributions of £29,600 a year are money you were previously funding yourselves. (3) The mortgage ends in 2044, not 2055.
C6: Pulling the other way: the return assumption has come down from a flat 10% to your 8% glidepath, which by 2055 has DM's pension earning 2.0% and the joint ISA 2.5%.
C8: THE LADDER — PICK YOUR RUNG
C9: DM's last full working year | D9: Base case | E9: DM's age | F9: Third child | G9: DM's age
C10: RUNG 1 — DM stops and the family lives partly off savings until MM's pension unlocks. This is the test you asked for: 'we can tap into earnings to cover expenses.' | D10: =Analysis_DM_Exit!$C$115 -> 2026 | E10: =Analysis_DM_Exit!$C$116 -> 44 | F10: =Analysis_Exit_3rd!$C$115 -> 2027 | G10: =Analysis_Exit_3rd!$C$116 -> 45
C11: RUNG 2 — DM stops and MM's pay alone covers everything, with no drawdown at all, ever. | D11: =Analysis_DM_Exit!$C$117 -> 2031 | E11: =Analysis_DM_Exit!$C$118 -> 49 | F11: =Analysis_Exit_3rd!$C$117 -> 2033 | G11: =Analysis_Exit_3rd!$C$118 -> 51
C12: RUNG 3 — as Rung 2, but with a 20% comfort margin on top. | D12: =Analysis_DM_Exit!$C$119 -> 2033 | E12: =Analysis_DM_Exit!$C$120 -> 51 | F12: =Analysis_Exit_3rd!$C$119 -> 2044 | G12: =Analysis_Exit_3rd!$C$120 -> 62
C14: Read that as: he could go now and be fine; he could go at 49 and never touch savings; he could go at 51 with room to spare.
C15: With a third child the same three rungs are 2027 (age 45), 2033 (age 51) and 2044 (age 62). The third rung jumps a long way because your post-maternity income of £180,000 is, in real terms, BELOW the £170,000 path it replaces — by 2034 MM's pay covers 1.17x of household spending, just under the 1.20x bar, and it only clears once the mortgage ends in 2045.
C17: WHAT 'ENOUGH' MEANS NOW (all three must pass — Assumptions rows 111 to 115)
C18: TEST 1 — SURVIVAL. From the year DM stops until MM turns 57 in 2048 and the pensions unlock, liquid savings must never fall below 12 months of household spending. This is the test that lets you live off savings.
C19: TEST 2 — BUFFER AT THE DOOR. On the day he stops: 12 months of spending PLUS £100,000 of business capital he could lose entirely.
C20: TEST 3 — RETIREMENT. With no further contributions from DM and only MM's contractual workplace pension continuing, the pensions must reach 25x adult-only spending by 2048, grossed up for tax on withdrawal.
C21: Test 3 is never close: the required pot is £2.76m and the projection lands at £7.6m even if DM stops in 2026. Test 2 passes from the start. Test 1 is the only one that ever fails, and only in the third-child case if DM goes in 2026.
C23: What Rung 1 actually looks like — DM stops at the end of 2026, no business income at all:
C24: Liquid savings dip from £302,000 to a low of £264,000 in 2028, then climb back. The annual gap is £45,000 in 2027 and £47,000 in 2028, narrowing to £14,000 by 2029 as EM's nursery ends and to nothing by 2032. From 2034 the nannies stop and the household is adding £26,000 a year again. The floor is £130,000 — the worst margin over it is £140,000, in 2028.
C26: THE JUNIOR ISAs — HOW MUCH, AND WHEN TO STOP
C27: Each pot is sized to cover three years of university PLUS the year of London living after graduation, and the model turns the £9,000 off the moment the pot on its own will get there. The target is the cost stream discounted back at 8%.
C28: Child | D28: Target fund | E28: Needed by | F28: £9,000 payments | G28: Total paid in | H28: Left over at 21
C29: VM (already has £15,000) | D29: =Children!$C$20 -> 121358.18 | E29: 2039 | F29: 4 — 2026 to 2029 | G29: 36000 | H29: =Children!$AF$26 -> 1871.5495
C30: EM (starting from zero) | D30: =Children!$C$32 -> 128786.27 | E30: 2042 | F30: 6 — 2026 to 2031 | G30: 54000 | H30: =Children!$AF$38 -> 40395.843
C31: Child 3 (scenario) | D31: =Children!$C$44 -> 136669.02 | E31: 2045 | F31: 6 — 2028 to 2033 | G31: 54000 | H31: =Children!$AF$50 -> 40275.844
C33: So the whole education bill is settled with £90,000 of Junior ISA contributions spread over six years, all finished by 2031 — and £144,000 over eight years if there is a third child. That is far less than the £9,000-a-year-forever plan in version 1, which would have put £324,000 into EM's pot alone.
C34: VM lands almost exactly on target (£1,872 spare). EM and Child 3 overshoot by about £40,000 each, because the last £9,000 payment tips them past the line — the rule you asked for is £9,000 or nothing. If you would rather land exactly, make the final payment a part payment; it saves roughly £7,000 of contribution in each case.
C36: Junior ISA rules that matter
C37: • £9,000 a year per child, entirely separate from your own £20,000 ISA allowances. Frozen at £9,000 until April 2031.
C38: • Nothing can be withdrawn before 18 — not by you, not by them.
C39: • At 18 the account becomes an adult ISA in the child's name. They control it, and they can spend it on anything. That is the real risk in over-funding, and the reason to stop once the pot is big enough.
C40: • Growth and withdrawals are free of income tax and capital gains tax.
C41: • Timing: VM turns 18 in December 2038 and starts university in October 2039 — clean. EM turns 18 on 14 December 2042 but starts in October 2042, so budget to fund his first term from household cash.
C43: CAN YOU MAX OUT THE PENSIONS AND ISAs? MOSTLY YES
C44: Base case: BOTH £60,000 pension allowances are filled every single year of the projection. In 2026 that is £52,200 of workplace contributions (yours plus your employers') and £67,800 of personal SIPP on top.
C45: The ISAs are the only thing that gets squeezed, and only at the start: £21,400 of the £40,000 in 2026 and £25,000 in 2027, because EM's nursery and both Junior ISAs are running at the same time. From 2028 both £20,000 allowances are filled every year.
C47: Third child: this is where it bites. The pension allowances CANNOT be filled in 2027, 2028 and 2029.
C48: Year | D48: Cash available | E48: SIPP headroom | F48: Actually paid in | G48: Allowance lost | H48: ISA
C49: 2027 | D49: =Scen_3rd_Child!D$36 -> 39608.6 | E49: =Scen_3rd_Child!D$38 -> 64452 | F49: =Scen_3rd_Child!D$41+Scen_3rd_Child!D$42 -> 49510.75 | G49: =Scen_3rd_Child!D$38-Scen_3rd_Child!D$41-Scen_3rd_Child!D$42 -> 14941.25 | H49: =Scen_3rd_Child!D$58 -> 15045.565
C50: 2028 | D50: =Scen_3rd_Child!E$36 -> 28520.652 | E50: =Scen_3rd_Child!E$38 -> 62230.08 | F50: =Scen_3rd_Child!E$41+Scen_3rd_Child!E$42 -> 35650.815 | G50: =Scen_3rd_Child!E$38-Scen_3rd_Child!E$41-Scen_3rd_Child!E$42 -> 26579.265 | H50: =Scen_3rd_Child!E$58 -> 9663.9321
...

Sheet Assumptions
A1: FAMILY JOINT FINANCES — 30-YEAR PROJECTION | ASSUMPTIONS (v2)
A2: Model years are CALENDAR years. Tax parameters use the UK tax year beginning in April of that year. School and university years begin in the September of that year. 2026 figures are as supplied by the family.
A3: COLOUR KEY: blue = an input you can change | black = formula | green = link to another sheet | yellow fill = key assumption
A5: 1. TIMELINE, INFLATION AND AGES
B6: Year | C6: 2026 | D6: 2027 | E6: 2028 | F6: 2029 | G6: 2030 | H6: 2031 | I6: 2032 | J6: 2033 | K6: 2034 | L6: 2035 | M6: 2036 | N6: 2037 | O6: 2038 | P6: 2039 | Q6: 2040 | R6: 2041 | S6: 2042 | T6: 2043 | U6: 2044 | V6: 2045 | W6: 2046 | X6: 2047 | Y6: 2048 | Z6: 2049 | AA6: 2050 | AB6: 2051 | AC6: 2052 | AD6: 2053 | AE6: 2054 | AF6: 2055
B7: Projection year | C7: 1 | D7: =C7+1 -> 2 | E7: =D7+1 -> 3 | F7: =E7+1 -> 4 | G7: =F7+1 -> 5 | H7: =G7+1 -> 6 | I7: =H7+1 -> 7 | J7: =I7+1 -> 8 | K7: =J7+1 -> 9 | ... AF7: =AE7+1 -> 30
B8: Inflation rate (applied to the prior year) | C8: 0 | D8: 0.04 | E8: 0.04 | F8: 0.02 | G8: 0.02 | H8: 0.02 | I8: 0.02 | J8: 0.02 | K8: 0.02 | L8: 0.02 | M8: 0.02 | N8: 0.02 | O8: 0.02 | P8: 0.02 | Q8: 0.02 | R8: 0.02 | S8: 0.02 | T8: 0.02 | U8: 0.02 | V8: 0.02 | W8: 0.02 | X8: 0.02 | Y8: 0.02 | Z8: 0.02 | AA8: 0.02 | AB8: 0.02 | AC8: 0.02 | AD8: 0.02 | AE8: 0.02 | AF8: 0.02 | AI8: User instruction: 4% for two years, then 2% to perpetuity.
B9: Inflation index (2026 = 1.000) | C9: 1 | D9: =C9*(1+D8) -> 1.04 | E9: =D9*(1+E8) -> 1.0816 | F9: =E9*(1+F8) -> 1.103232 | G9: =F9*(1+G8) -> 1.1252966 | H9: =G9*(1+H8) -> 1.1478026 | I9: =H9*(1+I8) -> 1.1707586 | J9: =I9*(1+J8) -> 1.1941738 | K9: =J9*(1+K8) -> 1.2180573 | ... AF9: =AE9*(1+AF8) -> 1.8461684
B10: Tax / allowance threshold uprating | C10: 0 | D10: 0 | E10: 0 | F10: 0 | G10: 0 | H10: =H8 -> 0.02 | I10: =I8 -> 0.02 | J10: =J8 -> 0.02 | K10: =K8 -> 0.02 | L10: =L8 -> 0.02 | M10: =M8 -> 0.02 | N10: =N8 -> 0.02 | O10: =O8 -> 0.02 | ... AF10: =AF8 -> 0.02 | AI10: Income-tax thresholds, the personal allowance and the pension / ISA / JISA allowances are frozen in cash terms to 2030/31 under current UK policy, then assumed to rise with inflation.
B11: Tax threshold index (2026 = 1.000) | C11: 1 | D11: =C11*(1+D10) -> 1 | E11: =D11*(1+E10) -> 1 | F11: =E11*(1+F10) -> 1 | G11: =F11*(1+G10) -> 1 | H11: =G11*(1+H10) -> 1.02 | I11: =H11*(1+I10) -> 1.0404 | J11: =I11*(1+J10) -> 1.061208 | K11: =J11*(1+K10) -> 1.0824322 | ... AF11: =AE11*(1+AF10) -> 1.640606
B12: MM age (at 31 December) | C12: 35 | D12: =C12+1 -> 36 | E12: =D12+1 -> 37 | F12: =E12+1 -> 38 | G12: =F12+1 -> 39 | H12: =G12+1 -> 40 | I12: =H12+1 -> 41 | J12: =I12+1 -> 42 | K12: =J12+1 -> 43 | ... AF12: =AE12+1 -> 64
B13: DM age (at 31 December) | C13: 44 | D13: =C13+1 -> 45 | E13: =D13+1 -> 46 | F13: =E13+1 -> 47 | G13: =F13+1 -> 48 | H13: =G13+1 -> 49 | I13: =H13+1 -> 50 | J13: =I13+1 -> 51 | K13: =J13+1 -> 52 | ... AF13: =AE13+1 -> 73
B14: Average age of MM and DM (drives the joint ISA glidepath) | C14: =(C12+C13)/2 -> 39.5 | D14: =(D12+D13)/2 -> 40.5 | E14: =(E12+E13)/2 -> 41.5 | F14: =(F12+F13)/2 -> 42.5 | G14: =(G12+G13)/2 -> 43.5 | H14: =(H12+H13)/2 -> 44.5 | I14: =(I12+I13)/2 -> 45.5 | J14: =(J12+J13)/2 -> 46.5 | ... AF14: =(AF12+AF13)/2 -> 68.5
B15: VM age | C15: 6 | D15: =C15+1 -> 7 | E15: =D15+1 -> 8 | F15: =E15+1 -> 9 | G15: =F15+1 -> 10 | H15: =G15+1 -> 11 | I15: =H15+1 -> 12 | J15: =I15+1 -> 13 | K15: =J15+1 -> 14 | ... AF15: =AE15+1 -> 35
B16: EM age | C16: 3 | D16: =C16+1 -> 4 | E16: =D16+1 -> 5 | F16: =E16+1 -> 6 | G16: =F16+1 -> 7 | H16: =G16+1 -> 8 | I16: =H16+1 -> 9 | J16: =I16+1 -> 10 | K16: =J16+1 -> 11 | ... AF16: =AE16+1 -> 32
B17: Child 3 age (scenario only) | C17: =IF(C6<2027,"",C6-2027) | D17: =IF(D6<2027,"",D6-2027) -> 0 | E17: =IF(E6<2027,"",E6-2027) -> 1 | F17: =IF(F6<2027,"",F6-2027) -> 2 | G17: =IF(G6<2027,"",G6-2027) -> 3 | H17: =IF(H6<2027,"",H6-2027) -> 4 | I17: =IF(I6<2027,"",I6-2027) -> 5 | J17: =IF(J6<2027,"",J6-2027) -> 6 | ... AF17: =IF(AF6<2027,"",AF6-2027) -> 28
A19: 2. THE TWO EARNERS — POSITION AT THE START OF 2026
C20: MM | D20: DM | E20: Source / note
B21: Total gross income (£/yr) | C21: 170000 | D21: 190000 | E21: Supplied by the family.
B22: Base salary in 2026 (£/yr) | C22: 100000 | D22: 130000 | E22: Supplied by the family. Base salary drives the workplace pension percentages.
B23: Base salary in 2027 (£/yr) — MM only | C23: 110000 | D23: 0 | E23: Supplied by the family. Set to 0 for DM, whose base simply grows with inflation.
B24: Age at 31 December 2026 | C24: 35 | D24: 44 | E24: Supplied by the family.
B25: ISA balance (£) | C25: 80000 | D25: 180000 | E25: Supplied by the family. The model runs these as ONE joint household pot.
B26: Pension balance (£) | C26: 480000 | D26: 760000 | E26: Supplied by the family.
B27: Personal expenses (£/month, 2026 prices) | C27: 1000 | D27: 800 | E27: Supplied by the family.
B28: Employee workplace pension (% of base salary) | C28: 0.07 | D28: 0.12 | E28: Supplied by the family.
B29: Employer workplace pension (% of base salary) | C29: 0.14 | D29: 0.12 | E29: Supplied by the family. Employer contributions count towards the £60,000 annual allowance.
A31: 3. INVESTMENT RETURNS
B32: Junior ISA return (flat, all years) | C32: 0.08 | E32: User instruction: Junior ISA return changed to 8%.
B33: Glidepath — return before the taper begins | C33: 0.08 | E33: User instruction: 'tapers from 8% to 2%'.
B34: Glidepath — age at which the taper begins | C34: 50 | E34: User instruction.
B35: Glidepath — return once the taper is complete | C35: 0.02 | E35: User instruction.
B36: Glidepath — age at which the taper is complete | C36: 70 | E36: User instruction.
B37: Tax drag on taxable (non-ISA) savings | C37: 0.015 | E37: Assumed dividend tax and CGT cost on a general investment account. Not supplied.
B38: Floor on the taxable-savings return | C38: 0.005 | E38: Stops the drag pushing the net return below zero late in the projection.
B39: Apply the glidepath to PENSIONS as well? (1 = yes) | C39: 1 | E39: YOU ONLY SPECIFIED THE ISA. Leaving pensions at a flat 8% while the ISA tapers would be inconsistent, so the same age glidepath is applied to each person's pension, using their own age. Set to 0 to hold pensions flat at the rate in C33.
A41: 4. CONTRIBUTION ALLOWANCES (2026/27 level, uprated by the threshold index)
B42: Pension annual allowance (each) | C42: 60000 | E42: £60,000 for 2026/27. Covers EMPLOYEE + EMPLOYER workplace contributions AND any personal SIPP contribution.
B43: ISA allowance (each) | C43: 20000 | E43: £20,000 for 2026/27.
B44: Junior ISA allowance (per child) | C44: 9000 | E44: £9,000 for 2026/27, separate from the adult ISA allowance and frozen until April 2031.
...

Sheet Tax_Bands
A1: UK TAX AND ALLOWANCE THRESHOLDS BY YEAR
A2: 2026/27 statutory figures, frozen in cash terms to 2030/31 (current UK policy) then uprated with inflation.
A4: THRESHOLDS AND RATES
B5: Year | C5: 2026 | D5: 2027 | E5: 2028 | F5: 2029 | G5: 2030 | H5: 2031 | I5: 2032 | J5: 2033 | K5: 2034 | L5: 2035 | M5: 2036 | N5: 2037 | O5: 2038 | P5: 2039 | Q5: 2040 | R5: 2041 | S5: 2042 | T5: 2043 | U5: 2044 | V5: 2045 | W5: 2046 | X5: 2047 | Y5: 2048 | Z5: 2049 | AA5: 2050 | AB5: 2051 | AC5: 2052 | AD5: 2053 | AE5: 2054 | AF5: 2055
B6: Threshold uprating index (2026 = 1.000) | C6: =Assumptions!C$11 -> 1 | D6: =Assumptions!D$11 -> 1 | E6: =Assumptions!E$11 -> 1 | F6: =Assumptions!F$11 -> 1 | G6: =Assumptions!G$11 -> 1 | H6: =Assumptions!H$11 -> 1.02 | I6: =Assumptions!I$11 -> 1.0404 | J6: =Assumptions!J$11 -> 1.061208 | ... AF6: =Assumptions!AF$11 -> 1.640606
B7: Personal allowance | C7: =Assumptions!$C$49*C$6 -> 12570 | D7: =Assumptions!$C$49*D$6 -> 12570 | E7: =Assumptions!$C$49*E$6 -> 12570 | F7: =Assumptions!$C$49*F$6 -> 12570 | G7: =Assumptions!$C$49*G$6 -> 12570 | H7: =Assumptions!$C$49*H$6 -> 12821.4 | I7: =Assumptions!$C$49*I$6 -> 13077.828 | J7: =Assumptions!$C$49*J$6 -> 13339.385 | ... AF7: =Assumptions!$C$49*AF$6 -> 20622.417
B8: Personal allowance taper starts | C8: =Assumptions!$C$50*C$6 -> 100000 | D8: =Assumptions!$C$50*D$6 -> 100000 | E8: =Assumptions!$C$50*E$6 -> 100000 | F8: =Assumptions!$C$50*F$6 -> 100000 | G8: =Assumptions!$C$50*G$6 -> 100000 | H8: =Assumptions!$C$50*H$6 -> 102000 | I8: =Assumptions!$C$50*I$6 -> 104040 | J8: =Assumptions!$C$50*J$6 -> 106120.8 | ... AF8: =Assumptions!$C$50*AF$6 -> 164060.6
B9: Basic rate limit (taxable income) | C9: =Assumptions!$C$51*C$6 -> 37700 | D9: =Assumptions!$C$51*D$6 -> 37700 | E9: =Assumptions!$C$51*E$6 -> 37700 | F9: =Assumptions!$C$51*F$6 -> 37700 | G9: =Assumptions!$C$51*G$6 -> 37700 | H9: =Assumptions!$C$51*H$6 -> 38454 | I9: =Assumptions!$C$51*I$6 -> 39223.08 | J9: =Assumptions!$C$51*J$6 -> 40007.542 | ... AF9: =Assumptions!$C$51*AF$6 -> 61850.846
B10: Additional rate threshold (taxable income) | C10: =Assumptions!$C$52*C$6 -> 125140 | D10: =Assumptions!$C$52*D$6 -> 125140 | E10: =Assumptions!$C$52*E$6 -> 125140 | F10: =Assumptions!$C$52*F$6 -> 125140 | G10: =Assumptions!$C$52*G$6 -> 125140 | H10: =Assumptions!$C$52*H$6 -> 127642.8 | I10: =Assumptions!$C$52*I$6 -> 130195.66 | J10: =Assumptions!$C$52*J$6 -> 132799.57 | ... AF10: =Assumptions!$C$52*AF$6 -> 205305.43
B11: National Insurance primary threshold | C11: =Assumptions!$C$56*C$6 -> 12570 | D11: =Assumptions!$C$56*D$6 -> 12570 | E11: =Assumptions!$C$56*E$6 -> 12570 | F11: =Assumptions!$C$56*F$6 -> 12570 | G11: =Assumptions!$C$56*G$6 -> 12570 | H11: =Assumptions!$C$56*H$6 -> 12821.4 | I11: =Assumptions!$C$56*I$6 -> 13077.828 | J11: =Assumptions!$C$56*J$6 -> 13339.385 | ... AF11: =Assumptions!$C$56*AF$6 -> 20622.417
B12: National Insurance upper earnings limit | C12: =Assumptions!$C$57*C$6 -> 50270 | D12: =Assumptions!$C$57*D$6 -> 50270 | E12: =Assumptions!$C$57*E$6 -> 50270 | F12: =Assumptions!$C$57*F$6 -> 50270 | G12: =Assumptions!$C$57*G$6 -> 50270 | H12: =Assumptions!$C$57*H$6 -> 51275.4 | I12: =Assumptions!$C$57*I$6 -> 52300.908 | J12: =Assumptions!$C$57*J$6 -> 53346.926 | ... AF12: =Assumptions!$C$57*AF$6 -> 82473.263
B13: Pension annual allowance (each) | C13: =Assumptions!$C$42*C$6 -> 60000 | D13: =Assumptions!$C$42*D$6 -> 60000 | E13: =Assumptions!$C$42*E$6 -> 60000 | F13: =Assumptions!$C$42*F$6 -> 60000 | G13: =Assumptions!$C$42*G$6 -> 60000 | H13: =Assumptions!$C$42*H$6 -> 61200 | I13: =Assumptions!$C$42*I$6 -> 62424 | J13: =Assumptions!$C$42*J$6 -> 63672.48 | ... AF13: =Assumptions!$C$42*AF$6 -> 98436.36
B14: Pension taper — adjusted income threshold | C14: =Assumptions!$C$45*C$6 -> 260000 | D14: =Assumptions!$C$45*D$6 -> 260000 | E14: =Assumptions!$C$45*E$6 -> 260000 | F14: =Assumptions!$C$45*F$6 -> 260000 | G14: =Assumptions!$C$45*G$6 -> 260000 | H14: =Assumptions!$C$45*H$6 -> 265200 | I14: =Assumptions!$C$45*I$6 -> 270504 | J14: =Assumptions!$C$45*J$6 -> 275914.08 | ... AF14: =Assumptions!$C$45*AF$6 -> 426557.56
B15: Pension taper — minimum annual allowance | C15: =Assumptions!$C$46*C$6 -> 10000 | D15: =Assumptions!$C$46*D$6 -> 10000 | E15: =Assumptions!$C$46*E$6 -> 10000 | F15: =Assumptions!$C$46*F$6 -> 10000 | G15: =Assumptions!$C$46*G$6 -> 10000 | H15: =Assumptions!$C$46*H$6 -> 10200 | I15: =Assumptions!$C$46*I$6 -> 10404 | J15: =Assumptions!$C$46*J$6 -> 10612.08 | ... AF15: =Assumptions!$C$46*AF$6 -> 16406.06
B16: ISA allowance (each) | C16: =Assumptions!$C$43*C$6 -> 20000 | D16: =Assumptions!$C$43*D$6 -> 20000 | E16: =Assumptions!$C$43*E$6 -> 20000 | F16: =Assumptions!$C$43*F$6 -> 20000 | G16: =Assumptions!$C$43*G$6 -> 20000 | H16: =Assumptions!$C$43*H$6 -> 20400 | I16: =Assumptions!$C$43*I$6 -> 20808 | J16: =Assumptions!$C$43*J$6 -> 21224.16 | ... AF16: =Assumptions!$C$43*AF$6 -> 32812.12
B17: Junior ISA allowance (per child) | C17: =Assumptions!$C$44*C$6 -> 9000 | D17: =Assumptions!$C$44*D$6 -> 9000 | E17: =Assumptions!$C$44*E$6 -> 9000 | F17: =Assumptions!$C$44*F$6 -> 9000 | G17: =Assumptions!$C$44*G$6 -> 9000 | H17: =Assumptions!$C$44*H$6 -> 9180 | I17: =Assumptions!$C$44*I$6 -> 9363.6 | J17: =Assumptions!$C$44*J$6 -> 9550.872 | ... AF17: =Assumptions!$C$44*AF$6 -> 14765.454
B18: Basic rate | C18: =Assumptions!$C$53 -> 0.2 | D18: =Assumptions!$C$53 -> 0.2 | E18: =Assumptions!$C$53 -> 0.2 | F18: =Assumptions!$C$53 -> 0.2 | G18: =Assumptions!$C$53 -> 0.2 | H18: =Assumptions!$C$53 -> 0.2 | I18: =Assumptions!$C$53 -> 0.2 | J18: =Assumptions!$C$53 -> 0.2 | ... AF18: =Assumptions!$C$53 -> 0.2
B19: Higher rate | C19: =Assumptions!$C$54 -> 0.4 | D19: =Assumptions!$C$54 -> 0.4 | E19: =Assumptions!$C$54 -> 0.4 | F19: =Assumptions!$C$54 -> 0.4 | G19: =Assumptions!$C$54 -> 0.4 | H19: =Assumptions!$C$54 -> 0.4 | I19: =Assumptions!$C$54 -> 0.4 | J19: =Assumptions!$C$54 -> 0.4 | ... AF19: =Assumptions!$C$54 -> 0.4
B20: Additional rate | C20: =Assumptions!$C$55 -> 0.45 | D20: =Assumptions!$C$55 -> 0.45 | E20: =Assumptions!$C$55 -> 0.45 | F20: =Assumptions!$C$55 -> 0.45 | G20: =Assumptions!$C$55 -> 0.45 | H20: =Assumptions!$C$55 -> 0.45 | I20: =Assumptions!$C$55 -> 0.45 | J20: =Assumptions!$C$55 -> 0.45 | ... AF20: =Assumptions!$C$55 -> 0.45
B21: NI main rate | C21: =Assumptions!$C$58 -> 0.08 | D21: =Assumptions!$C$58 -> 0.08 | E21: =Assumptions!$C$58 -> 0.08 | F21: =Assumptions!$C$58 -> 0.08 | G21: =Assumptions!$C$58 -> 0.08 | H21: =Assumptions!$C$58 -> 0.08 | I21: =Assumptions!$C$58 -> 0.08 | J21: =Assumptions!$C$58 -> 0.08 | ... AF21: =Assumptions!$C$58 -> 0.08
B22: NI upper rate | C22: =Assumptions!$C$59 -> 0.02 | D22: =Assumptions!$C$59 -> 0.02 | E22: =Assumptions!$C$59 -> 0.02 | F22: =Assumptions!$C$59 -> 0.02 | G22: =Assumptions!$C$59 -> 0.02 | H22: =Assumptions!$C$59 -> 0.02 | I22: =Assumptions!$C$59 -> 0.02 | J22: =Assumptions!$C$59 -> 0.02 | ... AF22: =Assumptions!$C$59 -> 0.02

Sheet Returns
A1: INVESTMENT RETURNS — THE AGE GLIDEPATH
A2: Junior ISAs earn a flat 8%. Every other pot follows the glidepath you specified: 8% until age 50, falling in a straight line to 2% at age 70. The joint ISA uses the AVERAGE of MM's and DM's ages because it is joint money; each pension uses its own owner's age.
A4: RATES BY YEAR
B5: Year | C5: 2026 | D5: 2027 | E5: 2028 | F5: 2029 | G5: 2030 | H5: 2031 | I5: 2032 | J5: 2033 | K5: 2034 | L5: 2035 | M5: 2036 | N5: 2037 | O5: 2038 | P5: 2039 | Q5: 2040 | R5: 2041 | S5: 2042 | T5: 2043 | U5: 2044 | V5: 2045 | W5: 2046 | X5: 2047 | Y5: 2048 | Z5: 2049 | AA5: 2050 | AB5: 2051 | AC5: 2052 | AD5: 2053 | AE5: 2054 | AF5: 2055
B6: MM age | C6: =Assumptions!C$12 -> 35 | D6: =Assumptions!D$12 -> 36 | E6: =Assumptions!E$12 -> 37 | F6: =Assumptions!F$12 -> 38 | G6: =Assumptions!G$12 -> 39 | H6: =Assumptions!H$12 -> 40 | I6: =Assumptions!I$12 -> 41 | J6: =Assumptions!J$12 -> 42 | ... AF6: =Assumptions!AF$12 -> 64
B7: DM age | C7: =Assumptions!C$13 -> 44 | D7: =Assumptions!D$13 -> 45 | E7: =Assumptions!E$13 -> 46 | F7: =Assumptions!F$13 -> 47 | G7: =Assumptions!G$13 -> 48 | H7: =Assumptions!H$13 -> 49 | I7: =Assumptions!I$13 -> 50 | J7: =Assumptions!J$13 -> 51 | ... AF7: =Assumptions!AF$13 -> 73
B8: Average age | C8: =Assumptions!C$14 -> 39.5 | D8: =Assumptions!D$14 -> 40.5 | E8: =Assumptions!E$14 -> 41.5 | F8: =Assumptions!F$14 -> 42.5 | G8: =Assumptions!G$14 -> 43.5 | H8: =Assumptions!H$14 -> 44.5 | I8: =Assumptions!I$14 -> 45.5 | J8: =Assumptions!J$14 -> 46.5 | ... AF8: =Assumptions!AF$14 -> 68.5
B9: MM pension return | C9: =IF(Assumptions!$C$39=1,MIN(Assumptions!$C$33,MAX(Assumptions!$C$35,Assumptions!$C$33-(Assumptions!$C$33-Assumptions!$C$35)*(C6-Assumptions!$C$34)/(Assumptions!$C$36-Assumptions!$C$34))),Assumptions!$C$33) -> 0.08 | D9: =IF(Assumptions!$C$39=1,MIN(Assumptions!$C$33,MAX(Assumptions!$C$35,Assumptions!$C$33-(Assumptions!$C$33-Assumptions!$C$35)*(D6-Assumptions!$C$34)/(Assumptions!$C$36-Assumptions!$C$34))),Assumptions!$C$33) -> 0.08 | E9: =IF(Assumptions!$C$39=1,MIN(Assumptions!$C$33,MAX(Assumptions!$C$35,Assumptions!$C$33-(Assumptions!$C$33-Assumptions!$C$35)*(E6-Assumptions!$C$34)/(Assumptions!$C$36-Assumptions!$C$34))),Assumptions!$C$33) -> 0.08 | F9: =IF(Assumptions!$C$39=1,MIN(Assumptions!$C$33,MAX(Assumptions!$C$35,Assumptions!$C$33-(Assumptions!$C$33-Assumptions!$C$35)*(F6-Assumptions!$C$34)/(Assumptions!$C$36-Assumptions!$C$34))),Assumptions!$C$33) -> 0.08 | G9: =IF(Assumptions!$C$39=1,MIN(Assumptions!$C$33,MAX(Assumptions!$C$35,Assumptions!$C$33-(Assumptions!$C$33-Assumptions!$C$35)*(G6-Assumptions!$C$34)/(Assumptions!$C$36-Assumptions!$C$34))),Assumptions!$C$33) -> 0.08 | H9: =IF(Assumptions!$C$39=1,MIN(Assumptions!$C$33,MAX(Assumptions!$C$35,Assumptions!$C$33-(Assumptions!$C$33-Assumptions!$C$35)*(H6-Assumptions!$C$34)/(Assumptions!$C$36-Assumptions!$C$34))),Assumptions!$C$33) -> 0.08 | I9: =IF(Assumptions!$C$39=1,MIN(Assumptions!$C$33,MAX(Assumptions!$C$35,Assumptions!$C$33-(Assumptions!$C$33-Assumptions!$C$35)*(I6-Assumptions!$C$34)/(Assumptions!$C$36-Assumptions!$C$34))),Assumptions!$C$33) -> 0.08 | J9: =IF(Assumptions!$C$39=1,MIN(Assumptions!$C$33,MAX(Assumptions!$C$35,Assumptions!$C$33-(Assumptions!$C$33-Assumptions!$C$35)*(J6-Assumptions!$C$34)/(Assumptions!$C$36-Assumptions!$C$34))),Assumptions!$C$33) -> 0.08 | ... AF9: =IF(Assumptions!$C$39=1,MIN(Assumptions!$C$33,MAX(Assumptions!$C$35,Assumptions!$C$33-(Assumptions!$C$33-Assumptions!$C$35)*(AF6-Assumptions!$C$34)/(Assumptions!$C$36-Assumptions!$C$34))),Assumptions!$C$33) -> 0.038
B10: DM pension return | C10: =IF(Assumptions!$C$39=1,MIN(Assumptions!$C$33,MAX(Assumptions!$C$35,Assumptions!$C$33-(Assumptions!$C$33-Assumptions!$C$35)*(C7-Assumptions!$C$34)/(Assumptions!$C$36-Assumptions!$C$34))),Assumptions!$C$33) -> 0.08 | D10: =IF(Assumptions!$C$39=1,MIN(Assumptions!$C$33,MAX(Assumptions!$C$35,Assumptions!$C$33-(Assumptions!$C$33-Assumptions!$C$35)*(D7-Assumptions!$C$34)/(Assumptions!$C$36-Assumptions!$C$34))),Assumptions!$C$33) -> 0.08 | E10: =IF(Assumptions!$C$39=1,MIN(Assumptions!$C$33,MAX(Assumptions!$C$35,Assumptions!$C$33-(Assumptions!$C$33-Assumptions!$C$35)*(E7-Assumptions!$C$34)/(Assumptions!$C$36-Assumptions!$C$34))),Assumptions!$C$33) -> 0.08 | F10: =IF(Assumptions!$C$39=1,MIN(Assumptions!$C$33,MAX(Assumptions!$C$35,Assumptions!$C$33-(Assumptions!$C$33-Assumptions!$C$35)*(F7-Assumptions!$C$34)/(Assumptions!$C$36-Assumptions!$C$34))),Assumptions!$C$33) -> 0.08 | G10: =IF(Assumptions!$C$39=1,MIN(Assumptions!$C$33,MAX(Assumptions!$C$35,Assumptions!$C$33-(Assumptions!$C$33-Assumptions!$C$35)*(G7-Assumptions!$C$34)/(Assumptions!$C$36-Assumptions!$C$34))),Assumptions!$C$33) -> 0.08 | H10: =IF(Assumptions!$C$39=1,MIN(Assumptions!$C$33,MAX(Assumptions!$C$35,Assumptions!$C$33-(Assumptions!$C$33-Assumptions!$C$35)*(H7-Assumptions!$C$34)/(Assumptions!$C$36-Assumptions!$C$34))),Assumptions!$C$33) -> 0.08 | I10: =IF(Assumptions!$C$39=1,MIN(Assumptions!$C$33,MAX(Assumptions!$C$35,Assumptions!$C$33-(Assumptions!$C$33-Assumptions!$C$35)*(I7-Assumptions!$C$34)/(Assumptions!$C$36-Assumptions!$C$34))),Assumptions!$C$33) -> 0.08 | J10: =IF(Assumptions!$C$39=1,MIN(Assumptions!$C$33,MAX(Assumptions!$C$35,Assumptions!$C$33-(Assumptions!$C$33-Assumptions!$C$35)*(J7-Assumptions!$C$34)/(Assumptions!$C$36-Assumptions!$C$34))),Assumptions!$C$33) -> 0.077 | ... AF10: =IF(Assumptions!$C$39=1,MIN(Assumptions!$C$33,MAX(Assumptions!$C$35,Assumptions!$C$33-(Assumptions!$C$33-Assumptions!$C$35)*(AF7-Assumptions!$C$34)/(Assumptions!$C$36-Assumptions!$C$34))),Assumptions!$C$33) -> 0.02
B11: Joint ISA return | C11: =MIN(Assumptions!$C$33,MAX(Assumptions!$C$35,Assumptions!$C$33-(Assumptions!$C$33-Assumptions!$C$35)*(C8-Assumptions!$C$34)/(Assumptions!$C$36-Assumptions!$C$34))) -> 0.08 | D11: =MIN(Assumptions!$C$33,MAX(Assumptions!$C$35,Assumptions!$C$33-(Assumptions!$C$33-Assumptions!$C$35)*(D8-Assumptions!$C$34)/(Assumptions!$C$36-Assumptions!$C$34))) -> 0.08 | E11: =MIN(Assumptions!$C$33,MAX(Assumptions!$C$35,Assumptions!$C$33-(Assumptions!$C$33-Assumptions!$C$35)*(E8-Assumptions!$C$34)/(Assumptions!$C$36-Assumptions!$C$34))) -> 0.08 | F11: =MIN(Assumptions!$C$33,MAX(Assumptions!$C$35,Assumptions!$C$33-(Assumptions!$C$33-Assumptions!$C$35)*(F8-Assumptions!$C$34)/(Assumptions!$C$36-Assumptions!$C$34))) -> 0.08 | G11: =MIN(Assumptions!$C$33,MAX(Assumptions!$C$35,Assumptions!$C$33-(Assumptions!$C$33-Assumptions!$C$35)*(G8-Assumptions!$C$34)/(Assumptions!$C$36-Assumptions!$C$34))) -> 0.08 | H11: =MIN(Assumptions!$C$33,MAX(Assumptions!$C$35,Assumptions!$C$33-(Assumptions!$C$33-Assumptions!$C$35)*(H8-Assumptions!$C$34)/(Assumptions!$C$36-Assumptions!$C$34))) -> 0.08 | I11: =MIN(Assumptions!$C$33,MAX(Assumptions!$C$35,Assumptions!$C$33-(Assumptions!$C$33-Assumptions!$C$35)*(I8-Assumptions!$C$34)/(Assumptions!$C$36-Assumptions!$C$34))) -> 0.08 | J11: =MIN(Assumptions!$C$33,MAX(Assumptions!$C$35,Assumptions!$C$33-(Assumptions!$C$33-Assumptions!$C$35)*(J8-Assumptions!$C$34)/(Assumptions!$C$36-Assumptions!$C$34))) -> 0.08 | ... AF11: =MIN(Assumptions!$C$33,MAX(Assumptions!$C$35,Assumptions!$C$33-(Assumptions!$C$33-Assumptions!$C$35)*(AF8-Assumptions!$C$34)/(Assumptions!$C$36-Assumptions!$C$34))) -> 0.0245
B12: Taxable (non-ISA) savings return | C12: =MAX(Assumptions!$C$38,C11-Assumptions!$C$37) -> 0.065 | D12: =MAX(Assumptions!$C$38,D11-Assumptions!$C$37) -> 0.065 | E12: =MAX(Assumptions!$C$38,E11-Assumptions!$C$37) -> 0.065 | F12: =MAX(Assumptions!$C$38,F11-Assumptions!$C$37) -> 0.065 | G12: =MAX(Assumptions!$C$38,G11-Assumptions!$C$37) -> 0.065 | H12: =MAX(Assumptions!$C$38,H11-Assumptions!$C$37) -> 0.065 | I12: =MAX(Assumptions!$C$38,I11-Assumptions!$C$37) -> 0.065 | J12: =MAX(Assumptions!$C$38,J11-Assumptions!$C$37) -> 0.065 | ... AF12: =MAX(Assumptions!$C$38,AF11-Assumptions!$C$37) -> 0.0095
B13: Junior ISA return | C13: =Assumptions!$C$32 -> 0.08 | D13: =Assumptions!$C$32 -> 0.08 | E13: =Assumptions!$C$32 -> 0.08 | F13: =Assumptions!$C$32 -> 0.08 | G13: =Assumptions!$C$32 -> 0.08 | H13: =Assumptions!$C$32 -> 0.08 | I13: =Assumptions!$C$32 -> 0.08 | J13: =Assumptions!$C$32 -> 0.08 | ... AF13: =Assumptions!$C$32 -> 0.08
A15: CUMULATIVE GROWTH FACTORS (used by the DM-exit sweep)
B16: Cumulative growth factor — MM pension | C16: =(1+C9) -> 1.08 | D16: =C16*(1+D9) -> 1.1664 | E16: =D16*(1+E9) -> 1.259712 | F16: =E16*(1+F9) -> 1.360489 | G16: =F16*(1+G9) -> 1.4693281 | H16: =G16*(1+H9) -> 1.5868743 | I16: =H16*(1+I9) -> 1.7138243 | J16: =I16*(1+J9) -> 1.8509302 | K16: =J16*(1+K9) -> 1.9990046 | ... AF16: =AE16*(1+AF9) -> 7.4869983
B17: Cumulative growth factor — DM pension | C17: =(1+C10) -> 1.08 | D17: =C17*(1+D10) -> 1.1664 | E17: =D17*(1+E10) -> 1.259712 | F17: =E17*(1+F10) -> 1.360489 | G17: =F17*(1+G10) -> 1.4693281 | H17: =G17*(1+H10) -> 1.5868743 | I17: =H17*(1+I10) -> 1.7138243 | J17: =I17*(1+J10) -> 1.8457887 | K17: =J17*(1+K10) -> 1.9823771 | ... AF17: =AE17*(1+AF10) -> 4.6768456
B18: Cumulative growth factor — Joint liquid savings | C18: =(1+C11) -> 1.08 | D18: =C18*(1+D11) -> 1.1664 | E18: =D18*(1+E11) -> 1.259712 | F18: =E18*(1+F11) -> 1.360489 | G18: =F18*(1+G11) -> 1.4693281 | H18: =G18*(1+H11) -> 1.5868743 | I18: =H18*(1+I11) -> 1.7138243 | J18: =I18*(1+J11) -> 1.8509302 | K18: =J18*(1+K11) -> 1.9990046 | ... AF18: =AE18*(1+AF11) -> 6.0399012
B20: MM workplace pension input (employee + employer) | C20: =MM_Income!C$12 -> 21000 | D20: =MM_Income!D$12 -> 23100 | E20: =MM_Income!E$12 -> 24024 | F20: =MM_Income!F$12 -> 24504.48 | G20: =MM_Income!G$12 -> 24994.57 | H20: =MM_Income!H$12 -> 25494.461 | I20: =MM_Income!I$12 -> 26004.35 | J20: =MM_Income!J$12 -> 26524.437 | ... AF20: =MM_Income!AF$12 -> 41006.241
B21: MM workplace input divided by the cumulative factor | C21: =C20/C16 -> 19444.444 | D21: =D20/D16 -> 19804.527 | E21: =E20/E16 -> 19071.026 | F21: =F20/F16 -> 18011.524 | G21: =G20/G16 -> 17010.884 | H21: =H20/H16 -> 16065.835 | I21: =I20/I16 -> 15173.289 | J21: =J20/J16 -> 14330.328 | ... AF21: =AF20/AF16 -> 5476.9935
B22: Running total of the row above | C22: =C21 -> 19444.444 | D22: =C22+D21 -> 39248.971 | E22: =D22+E21 -> 58319.997 | F22: =E22+F21 -> 76331.521 | G22: =F22+G21 -> 93342.405 | H22: =G22+H21 -> 109408.24 | I22: =H22+I21 -> 124581.53 | J22: =I22+J21 -> 138911.86 | K22: =J22+K21 -> 152446.06 | ... AF22: =AE22+AF21 -> 321809.41

Sheet MM_Income
A1: MM — INCOME, TAX, PENSION CONTRIBUTIONS AND BALANCE
A2: Workplace pension: NET PAY arrangement — the employee contribution reduces taxable pay but not National Insurance; the employer contribution is not taxable but does count towards the £60,000 annual allowance. Personal SIPP: RELIEF AT SOURCE — HMRC adds 20%, so £1 of gross costs 80p of cash, and the tax bands are extended by the gross contribution to give higher and additional-rate relief.
A4: MM — PAY AND PENSION INPUTS
B5: Year | C5: 2026 | D5: 2027 | E5: 2028 | F5: 2029 | G5: 2030 | H5: 2031 | I5: 2032 | J5: 2033 | K5: 2034 | L5: 2035 | M5: 2036 | N5: 2037 | O5: 2038 | P5: 2039 | Q5: 2040 | R5: 2041 | S5: 2042 | T5: 2043 | U5: 2044 | V5: 2045 | W5: 2046 | X5: 2047 | Y5: 2048 | Z5: 2049 | AA5: 2050 | AB5: 2051 | AC5: 2052 | AD5: 2053 | AE5: 2054 | AF5: 2055
B6: Age at 31 December | C6: =Assumptions!C$12 -> 35 | D6: =Assumptions!D$12 -> 36 | E6: =Assumptions!E$12 -> 37 | F6: =Assumptions!F$12 -> 38 | G6: =Assumptions!G$12 -> 39 | H6: =Assumptions!H$12 -> 40 | I6: =Assumptions!I$12 -> 41 | J6: =Assumptions!J$12 -> 42 | ... AF6: =Assumptions!AF$12 -> 64
B8: Total gross income | C8: =Assumptions!$C$21*Assumptions!C$9 -> 170000 | D8: =Assumptions!$C$21*Assumptions!D$9 -> 176800 | E8: =Assumptions!$C$21*Assumptions!E$9 -> 183872 | F8: =Assumptions!$C$21*Assumptions!F$9 -> 187549.44 | G8: =Assumptions!$C$21*Assumptions!G$9 -> 191300.43 | H8: =Assumptions!$C$21*Assumptions!H$9 -> 195126.44 | I8: =Assumptions!$C$21*Assumptions!I$9 -> 199028.97 | J8: =Assumptions!$C$21*Assumptions!J$9 -> 203009.55 | ... AF8: =Assumptions!$C$21*Assumptions!AF$9 -> 313848.63
B9: Base salary | C9: =Assumptions!$C$22 -> 100000 | D9: =IF(Assumptions!$C$23>0,Assumptions!$C$23*Assumptions!D$9/Assumptions!$D$9,Assumptions!$C$22*Assumptions!D$9) -> 110000 | E9: =IF(Assumptions!$C$23>0,Assumptions!$C$23*Assumptions!E$9/Assumptions!$D$9,Assumptions!$C$22*Assumptions!E$9) -> 114400 | F9: =IF(Assumptions!$C$23>0,Assumptions!$C$23*Assumptions!F$9/Assumptions!$D$9,Assumptions!$C$22*Assumptions!F$9) -> 116688 | G9: =IF(Assumptions!$C$23>0,Assumptions!$C$23*Assumptions!G$9/Assumptions!$D$9,Assumptions!$C$22*Assumptions!G$9) -> 119021.76 | H9: =IF(Assumptions!$C$23>0,Assumptions!$C$23*Assumptions!H$9/Assumptions!$D$9,Assumptions!$C$22*Assumptions!H$9) -> 121402.2 | I9: =IF(Assumptions!$C$23>0,Assumptions!$C$23*Assumptions!I$9/Assumptions!$D$9,Assumptions!$C$22*Assumptions!I$9) -> 123830.24 | J9: =IF(Assumptions!$C$23>0,Assumptions!$C$23*Assumptions!J$9/Assumptions!$D$9,Assumptions!$C$22*Assumptions!J$9) -> 126306.84 | K9: =IF(Assumptions!$C$23>0,Assumptions!$C$23*Assumptions!K$9/Assumptions!$D$9,Assumptions!$C$22*Assumptions!K$9) -> 128832.98 | ... AF9: =IF(Assumptions!$C$23>0,Assumptions!$C$23*Assumptions!AF$9/Assumptions!$D$9,Assumptions!$C$22*Assumptions!AF$9) -> 195267.81
B10: Employee workplace pension contribution | C10: =C9*Assumptions!$C$28 -> 7000 | D10: =D9*Assumptions!$C$28 -> 7700 | E10: =E9*Assumptions!$C$28 -> 8008 | F10: =F9*Assumptions!$C$28 -> 8168.16 | G10: =G9*Assumptions!$C$28 -> 8331.5232 | H10: =H9*Assumptions!$C$28 -> 8498.1537 | I10: =I9*Assumptions!$C$28 -> 8668.1167 | J10: =J9*Assumptions!$C$28 -> 8841.4791 | ... AF10: =AF9*Assumptions!$C$28 -> 13668.747
B11: Employer workplace pension contribution | C11: =C9*Assumptions!$C$29 -> 14000 | D11: =D9*Assumptions!$C$29 -> 15400 | E11: =E9*Assumptions!$C$29 -> 16016 | F11: =F9*Assumptions!$C$29 -> 16336.32 | G11: =G9*Assumptions!$C$29 -> 16663.046 | H11: =H9*Assumptions!$C$29 -> 16996.307 | I11: =I9*Assumptions!$C$29 -> 17336.233 | J11: =J9*Assumptions!$C$29 -> 17682.958 | ... AF11: =AF9*Assumptions!$C$29 -> 27337.494
B12: Total workplace pension input | C12: =C10+C11 -> 21000 | D12: =D10+D11 -> 23100 | E12: =E10+E11 -> 24024 | F12: =F10+F11 -> 24504.48 | G12: =G10+G11 -> 24994.57 | H12: =H10+H11 -> 25494.461 | I12: =I10+I11 -> 26004.35 | J12: =J10+J11 -> 26524.437 | ... AF12: =AF10+AF11 -> 41006.241
B13: Adjusted income (for the annual allowance taper) | C13: =C8+C11 -> 184000 | D13: =D8+D11 -> 192200 | E13: =E8+E11 -> 199888 | F13: =F8+F11 -> 203885.76 | G13: =G8+G11 -> 207963.48 | H13: =H8+H11 -> 212122.74 | I13: =I8+I11 -> 216365.2 | J13: =J8+J11 -> 220692.5 | ... AF13: =AF8+AF11 -> 341186.12
B14: Annual allowance available after any taper | C14: =MAX(Tax_Bands!C$15,Tax_Bands!C$13-MAX(0,C13-Tax_Bands!C$14)/2) -> 60000 | D14: =MAX(Tax_Bands!D$15,Tax_Bands!D$13-MAX(0,D13-Tax_Bands!D$14)/2) -> 60000 | E14: =MAX(Tax_Bands!E$15,Tax_Bands!E$13-MAX(0,E13-Tax_Bands!E$14)/2) -> 60000 | F14: =MAX(Tax_Bands!F$15,Tax_Bands!F$13-MAX(0,F13-Tax_Bands!F$14)/2) -> 60000 | G14: =MAX(Tax_Bands!G$15,Tax_Bands!G$13-MAX(0,G13-Tax_Bands!G$14)/2) -> 60000 | H14: =MAX(Tax_Bands!H$15,Tax_Bands!H$13-MAX(0,H13-Tax_Bands!H$14)/2) -> 61200 | I14: =MAX(Tax_Bands!I$15,Tax_Bands!I$13-MAX(0,I13-Tax_Bands!I$14)/2) -> 62424 | J14: =MAX(Tax_Bands!J$15,Tax_Bands!J$13-MAX(0,J13-Tax_Bands!J$14)/2) -> 63672.48 | ... AF14: =MAX(Tax_Bands!AF$15,Tax_Bands!AF$13-MAX(0,AF13-Tax_Bands!AF$14)/2) -> 98436.36
B15: SIPP HEADROOM (allowance less workplace contributions) | C15: =MAX(0,MIN(C14-C12,C8-C10)) -> 39000 | D15: =MAX(0,MIN(D14-D12,D8-D10)) -> 36900 | E15: =MAX(0,MIN(E14-E12,E8-E10)) -> 35976 | F15: =MAX(0,MIN(F14-F12,F8-F10)) -> 35495.52 | G15: =MAX(0,MIN(G14-G12,G8-G10)) -> 35005.43 | H15: =MAX(0,MIN(H14-H12,H8-H10)) -> 35705.539 | I15: =MAX(0,MIN(I14-I12,I8-I10)) -> 36419.65 | J15: =MAX(0,MIN(J14-J12,J8-J10)) -> 37148.043 | ... AF15: =MAX(0,MIN(AF14-AF12,AF8-AF10)) -> 57430.119
A16: MM — TAX BEFORE ANY PERSONAL SIPP CONTRIBUTION
B17: Taxable pay (income less the employee workplace contribution) | C17: =C8-C10 -> 163000 | D17: =D8-D10 -> 169100 | E17: =E8-E10 -> 175864 | F17: =F8-F10 -> 179381.28 | G17: =G8-G10 -> 182968.91 | H17: =H8-H10 -> 186628.28 | I17: =I8-I10 -> 190360.85 | J17: =J8-J10 -> 194168.07 | ... AF17: =AF8-AF10 -> 300179.88
B18: Personal allowance after taper | C18: =MAX(0,Tax_Bands!C$7-MAX(0,C17-Tax_Bands!C$8)/2) -> 0 | D18: =MAX(0,Tax_Bands!D$7-MAX(0,D17-Tax_Bands!D$8)/2) -> 0 | E18: =MAX(0,Tax_Bands!E$7-MAX(0,E17-Tax_Bands!E$8)/2) -> 0 | F18: =MAX(0,Tax_Bands!F$7-MAX(0,F17-Tax_Bands!F$8)/2) -> 0 | G18: =MAX(0,Tax_Bands!G$7-MAX(0,G17-Tax_Bands!G$8)/2) -> 0 | H18: =MAX(0,Tax_Bands!H$7-MAX(0,H17-Tax_Bands!H$8)/2) -> 0 | I18: =MAX(0,Tax_Bands!I$7-MAX(0,I17-Tax_Bands!I$8)/2) -> 0 | J18: =MAX(0,Tax_Bands!J$7-MAX(0,J17-Tax_Bands!J$8)/2) -> 0 | ... AF18: =MAX(0,Tax_Bands!AF$7-MAX(0,AF17-Tax_Bands!AF$8)/2) -> 0
B19: Taxable income | C19: =MAX(0,C17-C18) -> 163000 | D19: =MAX(0,D17-D18) -> 169100 | E19: =MAX(0,E17-E18) -> 175864 | F19: =MAX(0,F17-F18) -> 179381.28 | G19: =MAX(0,G17-G18) -> 182968.91 | H19: =MAX(0,H17-H18) -> 186628.28 | I19: =MAX(0,I17-I18) -> 190360.85 | J19: =MAX(0,J17-J18) -> 194168.07 | ... AF19: =MAX(0,AF17-AF18) -> 300179.88
B20: Income tax | C20: =Tax_Bands!C$18*MIN(C19,Tax_Bands!C$9)+Tax_Bands!C$19*MAX(0,MIN(C19,Tax_Bands!C$10)-Tax_Bands!C$9)+Tax_Bands!C$20*MAX(0,C19-Tax_Bands!C$10) -> 59553 | D20: =Tax_Bands!D$18*MIN(D19,Tax_Bands!D$9)+Tax_Bands!D$19*MAX(0,MIN(D19,Tax_Bands!D$10)-Tax_Bands!D$9)+Tax_Bands!D$20*MAX(0,D19-Tax_Bands!D$10) -> 62298 | E20: =Tax_Bands!E$18*MIN(E19,Tax_Bands!E$9)+Tax_Bands!E$19*MAX(0,MIN(E19,Tax_Bands!E$10)-Tax_Bands!E$9)+Tax_Bands!E$20*MAX(0,E19-Tax_Bands!E$10) -> 65341.8 | F20: =Tax_Bands!F$18*MIN(F19,Tax_Bands!F$9)+Tax_Bands!F$19*MAX(0,MIN(F19,Tax_Bands!F$10)-Tax_Bands!F$9)+Tax_Bands!F$20*MAX(0,F19-Tax_Bands!F$10) -> 66924.576 | G20: =Tax_Bands!G$18*MIN(G19,Tax_Bands!G$9)+Tax_Bands!G$19*MAX(0,MIN(G19,Tax_Bands!G$10)-Tax_Bands!G$9)+Tax_Bands!G$20*MAX(0,G19-Tax_Bands!G$10) -> 68539.008 | H20: =Tax_Bands!H$18*MIN(H19,Tax_Bands!H$9)+Tax_Bands!H$19*MAX(0,MIN(H19,Tax_Bands!H$10)-Tax_Bands!H$9)+Tax_Bands!H$20*MAX(0,H19-Tax_Bands!H$10) -> 69909.788 | I20: =Tax_Bands!I$18*MIN(I19,Tax_Bands!I$9)+Tax_Bands!I$19*MAX(0,MIN(I19,Tax_Bands!I$10)-Tax_Bands!I$9)+Tax_Bands!I$20*MAX(0,I19-Tax_Bands!I$10) -> 71307.983 | J20: =Tax_Bands!J$18*MIN(J19,Tax_Bands!J$9)+Tax_Bands!J$19*MAX(0,MIN(J19,Tax_Bands!J$10)-Tax_Bands!J$9)+Tax_Bands!J$20*MAX(0,J19-Tax_Bands!J$10) -> 72734.143 | ... AF20: =Tax_Bands!AF$18*MIN(AF19,Tax_Bands!AF$9)+Tax_Bands!AF$19*MAX(0,MIN(AF19,Tax_Bands!AF$10)-Tax_Bands!AF$9)+Tax_Bands!AF$20*MAX(0,AF19-Tax_Bands!AF$10) -> 112445.51
B21: Employee National Insurance | C21: =Tax_Bands!C$21*MAX(0,MIN(C8,Tax_Bands!C$12)-Tax_Bands!C$11)+Tax_Bands!C$22*MAX(0,C8-Tax_Bands!C$12) -> 5410.6 | D21: =Tax_Bands!D$21*MAX(0,MIN(D8,Tax_Bands!D$12)-Tax_Bands!D$11)+Tax_Bands!D$22*MAX(0,D8-Tax_Bands!D$12) -> 5546.6 | E21: =Tax_Bands!E$21*MAX(0,MIN(E8,Tax_Bands!E$12)-Tax_Bands!E$11)+Tax_Bands!E$22*MAX(0,E8-Tax_Bands!E$12) -> 5688.04 | F21: =Tax_Bands!F$21*MAX(0,MIN(F8,Tax_Bands!F$12)-Tax_Bands!F$11)+Tax_Bands!F$22*MAX(0,F8-Tax_Bands!F$12) -> 5761.5888 | G21: =Tax_Bands!G$21*MAX(0,MIN(G8,Tax_Bands!G$12)-Tax_Bands!G$11)+Tax_Bands!G$22*MAX(0,G8-Tax_Bands!G$12) -> 5836.6086 | H21: =Tax_Bands!H$21*MAX(0,MIN(H8,Tax_Bands!H$12)-Tax_Bands!H$11)+Tax_Bands!H$22*MAX(0,H8-Tax_Bands!H$12) -> 5953.3407 | I21: =Tax_Bands!I$21*MAX(0,MIN(I8,Tax_Bands!I$12)-Tax_Bands!I$11)+Tax_Bands!I$22*MAX(0,I8-Tax_Bands!I$12) -> 6072.4076 | J21: =Tax_Bands!J$21*MAX(0,MIN(J8,Tax_Bands!J$12)-Tax_Bands!J$11)+Tax_Bands!J$22*MAX(0,J8-Tax_Bands!J$12) -> 6193.8557 | ... AF21: =Tax_Bands!AF$21*MAX(0,MIN(AF8,Tax_Bands!AF$12)-Tax_Bands!AF$11)+Tax_Bands!AF$22*MAX(0,AF8-Tax_Bands!AF$12) -> 9575.575
B22: NET PAY (cash in hand before any personal SIPP contribution) | C22: =C17-C20-C21 -> 98036.4 | D22: =D17-D20-D21 -> 101255.4 | E22: =E17-E20-E21 -> 104834.16 | F22: =F17-F20-F21 -> 106695.12 | G22: =G17-G20-G21 -> 108593.29 | H22: =H17-H20-H21 -> 110765.16 | I22: =I17-I20-I21 -> 112980.46 | J22: =J17-J20-J21 -> 115240.07 | ... AF22: =AF17-AF20-AF21 -> 178158.8
A23: MM — WITH THE PERSONAL SIPP CONTRIBUTION ACTUALLY AFFORDED
B24: Personal SIPP contribution (gross) | C24: =Household_Base!C$37 -> 39000 | D24: =Household_Base!D$37 -> 36900 | E24: =Household_Base!E$37 -> 35976 | F24: =Household_Base!F$37 -> 35495.52 | G24: =Household_Base!G$37 -> 35005.43 | H24: =Household_Base!H$37 -> 35705.539 | I24: =Household_Base!I$37 -> 36419.65 | J24: =Household_Base!J$37 -> 37148.043 | ... AF24: =Household_Base!AF$37 -> 57430.119
B25: Adjusted net income | C25: =C17-C24 -> 124000 | D25: =D17-D24 -> 132200 | E25: =E17-E24 -> 139888 | F25: =F17-F24 -> 143885.76 | G25: =G17-G24 -> 147963.48 | H25: =H17-H24 -> 150922.74 | I25: =I17-I24 -> 153941.2 | J25: =J17-J24 -> 157020.02 | ... AF25: =AF17-AF24 -> 242749.76
B26: Personal allowance after taper | C26: =MAX(0,Tax_Bands!C$7-MAX(0,C25-Tax_Bands!C$8)/2) -> 570 | D26: =MAX(0,Tax_Bands!D$7-MAX(0,D25-Tax_Bands!D$8)/2) -> 0 | E26: =MAX(0,Tax_Bands!E$7-MAX(0,E25-Tax_Bands!E$8)/2) -> 0 | F26: =MAX(0,Tax_Bands!F$7-MAX(0,F25-Tax_Bands!F$8)/2) -> 0 | G26: =MAX(0,Tax_Bands!G$7-MAX(0,G25-Tax_Bands!G$8)/2) -> 0 | H26: =MAX(0,Tax_Bands!H$7-MAX(0,H25-Tax_Bands!H$8)/2) -> 0 | I26: =MAX(0,Tax_Bands!I$7-MAX(0,I25-Tax_Bands!I$8)/2) -> 0 | J26: =MAX(0,Tax_Bands!J$7-MAX(0,J25-Tax_Bands!J$8)/2) -> 0 | ... AF26: =MAX(0,Tax_Bands!AF$7-MAX(0,AF25-Tax_Bands!AF$8)/2) -> 0
B27: Taxable income | C27: =MAX(0,C17-C26) -> 162430 | D27: =MAX(0,D17-D26) -> 169100 | E27: =MAX(0,E17-E26) -> 175864 | F27: =MAX(0,F17-F26) -> 179381.28 | G27: =MAX(0,G17-G26) -> 182968.91 | H27: =MAX(0,H17-H26) -> 186628.28 | I27: =MAX(0,I17-I26) -> 190360.85 | J27: =MAX(0,J17-J26) -> 194168.07 | ... AF27: =MAX(0,AF17-AF26) -> 300179.88
B28: Income tax | C28: =Tax_Bands!C$18*MIN(C27,Tax_Bands!C$9+C24)+Tax_Bands!C$19*MAX(0,MIN(C27,Tax_Bands!C$10+C24)-(Tax_Bands!C$9+C24))+Tax_Bands!C$20*MAX(0,C27-(Tax_Bands!C$10+C24)) -> 49632 | D28: =Tax_Bands!D$18*MIN(D27,Tax_Bands!D$9+D24)+Tax_Bands!D$19*MAX(0,MIN(D27,Tax_Bands!D$10+D24)-(Tax_Bands!D$9+D24))+Tax_Bands!D$20*MAX(0,D27-(Tax_Bands!D$10+D24)) -> 53073 | E28: =Tax_Bands!E$18*MIN(E27,Tax_Bands!E$9+E24)+Tax_Bands!E$19*MAX(0,MIN(E27,Tax_Bands!E$10+E24)-(Tax_Bands!E$9+E24))+Tax_Bands!E$20*MAX(0,E27-(Tax_Bands!E$10+E24)) -> 56347.8 | F28: =Tax_Bands!F$18*MIN(F27,Tax_Bands!F$9+F24)+Tax_Bands!F$19*MAX(0,MIN(F27,Tax_Bands!F$10+F24)-(Tax_Bands!F$9+F24))+Tax_Bands!F$20*MAX(0,F27-(Tax_Bands!F$10+F24)) -> 58050.696 | G28: =Tax_Bands!G$18*MIN(G27,Tax_Bands!G$9+G24)+Tax_Bands!G$19*MAX(0,MIN(G27,Tax_Bands!G$10+G24)-(Tax_Bands!G$9+G24))+Tax_Bands!G$20*MAX(0,G27-(Tax_Bands!G$10+G24)) -> 59787.65 | H28: =Tax_Bands!H$18*MIN(H27,Tax_Bands!H$9+H24)+Tax_Bands!H$19*MAX(0,MIN(H27,Tax_Bands!H$10+H24)-(Tax_Bands!H$9+H24))+Tax_Bands!H$20*MAX(0,H27-(Tax_Bands!H$10+H24)) -> 60983.403 | I28: =Tax_Bands!I$18*MIN(I27,Tax_Bands!I$9+I24)+Tax_Bands!I$19*MAX(0,MIN(I27,Tax_Bands!I$10+I24)-(Tax_Bands!I$9+I24))+Tax_Bands!I$20*MAX(0,I27-(Tax_Bands!I$10+I24)) -> 62203.071 | J28: =Tax_Bands!J$18*MIN(J27,Tax_Bands!J$9+J24)+Tax_Bands!J$19*MAX(0,MIN(J27,Tax_Bands!J$10+J24)-(Tax_Bands!J$9+J24))+Tax_Bands!J$20*MAX(0,J27-(Tax_Bands!J$10+J24)) -> 63447.132 | ... AF28: =Tax_Bands!AF$18*MIN(AF27,Tax_Bands!AF$9+AF24)+Tax_Bands!AF$19*MAX(0,MIN(AF27,Tax_Bands!AF$10+AF24)-(Tax_Bands!AF$9+AF24))+Tax_Bands!AF$20*MAX(0,AF27-(Tax_Bands!AF$10+AF24)) -> 98087.977
B29: Higher / additional-rate relief recovered | C29: =C20-C28 -> 9921 | D29: =D20-D28 -> 9225 | E29: =E20-E28 -> 8994 | F29: =F20-F28 -> 8873.88 | G29: =G20-G28 -> 8751.3576 | H29: =H20-H28 -> 8926.3848 | I29: =I20-I28 -> 9104.9124 | J29: =J20-J28 -> 9287.0107 | ... AF29: =AF20-AF28 -> 14357.53
B30: POST-TAX INCOME (gross income less income tax and NI) | C30: =C8-C28-C21 -> 114957.4 | D30: =D8-D28-D21 -> 118180.4 | E30: =E8-E28-E21 -> 121836.16 | F30: =F8-F28-F21 -> 123737.16 | G30: =G8-G28-G21 -> 125676.17 | H30: =H8-H28-H21 -> 128189.69 | I30: =I8-I28-I21 -> 130753.49 | J30: =J8-J28-J21 -> 133368.56 | ... AF30: =AF8-AF28-AF21 -> 206185.08
B31: Effective income tax + NI rate | C31: =IF(C8=0,0,(C28+C21)/C8) -> 0.32378 | D31: =IF(D8=0,0,(D28+D21)/D8) -> 0.33155882 | E31: =IF(E8=0,0,(E28+E21)/E8) -> 0.33738601 | F31: =IF(F8=0,0,(F28+F21)/F8) -> 0.34024247 | G31: =IF(G8=0,0,(G28+G21)/G8) -> 0.34304292 | H31: =IF(H8=0,0,(H28+H21)/H8) -> 0.34304292 | I31: =IF(I8=0,0,(I28+I21)/I8) -> 0.34304292 | J31: =IF(J8=0,0,(J28+J21)/J8) -> 0.34304292 | ... AF31: =IF(AF8=0,0,(AF28+AF21)/AF8) -> 0.34304292
A32: MM — PENSION BALANCE
B33: Opening balance | C33: =Assumptions!$C$26 -> 480000 | D33: =C37 -> 578400 | E33: =D37 -> 684672 | F33: =E37 -> 799445.76 | G33: =F37 -> 923401.42 | H33: =G37 -> 1057273.5 | I33: =H37 -> 1203055.4 | J33: =I37 -> 1361723.9 | K33: =J37 -> 1534334.2 | ... AF33: =AE37 -> 9051152.7
B34: Add: workplace contributions (employee + employer) | C34: =C12 -> 21000 | D34: =D12 -> 23100 | E34: =E12 -> 24024 | F34: =F12 -> 24504.48 | G34: =G12 -> 24994.57 | H34: =H12 -> 25494.461 | I34: =I12 -> 26004.35 | J34: =J12 -> 26524.437 | ... AF34: =AF12 -> 41006.241
B35: Add: personal SIPP contribution | C35: =C24 -> 39000 | D35: =D24 -> 36900 | E35: =E24 -> 35976 | F35: =F24 -> 35495.52 | G35: =G24 -> 35005.43 | H35: =H24 -> 35705.539 | I35: =I24 -> 36419.65 | J35: =J24 -> 37148.043 | ... AF35: =AF24 -> 57430.119
B36: Add: investment growth | C36: =C33*Returns!C$9 -> 38400 | D36: =D33*Returns!D$9 -> 46272 | E36: =E33*Returns!E$9 -> 54773.76 | F36: =F33*Returns!F$9 -> 63955.661 | G36: =G33*Returns!G$9 -> 73872.114 | H36: =H33*Returns!H$9 -> 84581.883 | I36: =I33*Returns!I$9 -> 96244.433 | J36: =J33*Returns!J$9 -> 108937.91 | ... AF36: =AF33*Returns!AF$9 -> 343943.8
B37: CLOSING BALANCE | C37: =C33+C34+C35+C36 -> 578400 | D37: =D33+D34+D35+D36 -> 684672 | E37: =E33+E34+E35+E36 -> 799445.76 | F37: =F33+F34+F35+F36 -> 923401.42 | G37: =G33+G34+G35+G36 -> 1057273.5 | H37: =H33+H34+H35+H36 -> 1203055.4 | I37: =I33+I34+I35+I36 -> 1361723.9 | J37: =J33+J34+J35+J36 -> 1534334.2 | ... AF37: =AF33+AF34+AF35+AF36 -> 9493532.9

Sheet DM_Income
A1: DM — INCOME, TAX, PENSION CONTRIBUTIONS AND BALANCE
A2: Workplace pension: NET PAY arrangement — the employee contribution reduces taxable pay but not National Insurance; the employer contribution is not taxable but does count towards the £60,000 annual allowance. Personal SIPP: RELIEF AT SOURCE — HMRC adds 20%, so £1 of gross costs 80p of cash, and the tax bands are extended by the gross contribution to give higher and additional-rate relief.
A4: DM — PAY AND PENSION INPUTS
B5: Year | C5: 2026 | D5: 2027 | E5: 2028 | F5: 2029 | G5: 2030 | H5: 2031 | I5: 2032 | J5: 2033 | K5: 2034 | L5: 2035 | M5: 2036 | N5: 2037 | O5: 2038 | P5: 2039 | Q5: 2040 | R5: 2041 | S5: 2042 | T5: 2043 | U5: 2044 | V5: 2045 | W5: 2046 | X5: 2047 | Y5: 2048 | Z5: 2049 | AA5: 2050 | AB5: 2051 | AC5: 2052 | AD5: 2053 | AE5: 2054 | AF5: 2055
B6: Age at 31 December | C6: =Assumptions!C$13 -> 44 | D6: =Assumptions!D$13 -> 45 | E6: =Assumptions!E$13 -> 46 | F6: =Assumptions!F$13 -> 47 | G6: =Assumptions!G$13 -> 48 | H6: =Assumptions!H$13 -> 49 | I6: =Assumptions!I$13 -> 50 | J6: =Assumptions!J$13 -> 51 | ... AF6: =Assumptions!AF$13 -> 73
B8: Total gross income | C8: =Assumptions!$D$21*Assumptions!C$9 -> 190000 | D8: =Assumptions!$D$21*Assumptions!D$9 -> 197600 | E8: =Assumptions!$D$21*Assumptions!E$9 -> 205504 | F8: =Assumptions!$D$21*Assumptions!F$9 -> 209614.08 | G8: =Assumptions!$D$21*Assumptions!G$9 -> 213806.36 | H8: =Assumptions!$D$21*Assumptions!H$9 -> 218082.49 | I8: =Assumptions!$D$21*Assumptions!I$9 -> 222444.14 | J8: =Assumptions!$D$21*Assumptions!J$9 -> 226893.02 | ... AF8: =Assumptions!$D$21*Assumptions!AF$9 -> 350772
B9: Base salary | C9: =Assumptions!$D$22 -> 130000 | D9: =IF(Assumptions!$D$23>0,Assumptions!$D$23*Assumptions!D$9/Assumptions!$D$9,Assumptions!$D$22*Assumptions!D$9) -> 135200 | E9: =IF(Assumptions!$D$23>0,Assumptions!$D$23*Assumptions!E$9/Assumptions!$D$9,Assumptions!$D$22*Assumptions!E$9) -> 140608 | F9: =IF(Assumptions!$D$23>0,Assumptions!$D$23*Assumptions!F$9/Assumptions!$D$9,Assumptions!$D$22*Assumptions!F$9) -> 143420.16 | G9: =IF(Assumptions!$D$23>0,Assumptions!$D$23*Assumptions!G$9/Assumptions!$D$9,Assumptions!$D$22*Assumptions!G$9) -> 146288.56 | H9: =IF(Assumptions!$D$23>0,Assumptions!$D$23*Assumptions!H$9/Assumptions!$D$9,Assumptions!$D$22*Assumptions!H$9) -> 149214.33 | I9: =IF(Assumptions!$D$23>0,Assumptions!$D$23*Assumptions!I$9/Assumptions!$D$9,Assumptions!$D$22*Assumptions!I$9) -> 152198.62 | J9: =IF(Assumptions!$D$23>0,Assumptions!$D$23*Assumptions!J$9/Assumptions!$D$9,Assumptions!$D$22*Assumptions!J$9) -> 155242.59 | K9: =IF(Assumptions!$D$23>0,Assumptions!$D$23*Assumptions!K$9/Assumptions!$D$9,Assumptions!$D$22*Assumptions!K$9) -> 158347.45 | ... AF9: =IF(Assumptions!$D$23>0,Assumptions!$D$23*Assumptions!AF$9/Assumptions!$D$9,Assumptions!$D$22*Assumptions!AF$9) -> 240001.89
B10: Employee workplace pension contribution | C10: =C9*Assumptions!$D$28 -> 15600 | D10: =D9*Assumptions!$D$28 -> 16224 | E10: =E9*Assumptions!$D$28 -> 16872.96 | F10: =F9*Assumptions!$D$28 -> 17210.419 | G10: =G9*Assumptions!$D$28 -> 17554.628 | H10: =H9*Assumptions!$D$28 -> 17905.72 | I10: =I9*Assumptions!$D$28 -> 18263.835 | J10: =J9*Assumptions!$D$28 -> 18629.111 | ... AF10: =AF9*Assumptions!$D$28 -> 28800.227
B11: Employer workplace pension contribution | C11: =C9*Assumptions!$D$29 -> 15600 | D11: =D9*Assumptions!$D$29 -> 16224 | E11: =E9*Assumptions!$D$29 -> 16872.96 | F11: =F9*Assumptions!$D$29 -> 17210.419 | G11: =G9*Assumptions!$D$29 -> 17554.628 | H11: =H9*Assumptions!$D$29 -> 17905.72 | I11: =I9*Assumptions!$D$29 -> 18263.835 | J11: =J9*Assumptions!$D$29 -> 18629.111 | ... AF11: =AF9*Assumptions!$D$29 -> 28800.227
B12: Total workplace pension input | C12: =C10+C11 -> 31200 | D12: =D10+D11 -> 32448 | E12: =E10+E11 -> 33745.92 | F12: =F10+F11 -> 34420.838 | G12: =G10+G11 -> 35109.255 | H12: =H10+H11 -> 35811.44 | I12: =I10+I11 -> 36527.669 | J12: =J10+J11 -> 37258.222 | ... AF12: =AF10+AF11 -> 57600.454
B13: Adjusted income (for the annual allowance taper) | C13: =C8+C11 -> 205600 | D13: =D8+D11 -> 213824 | E13: =E8+E11 -> 222376.96 | F13: =F8+F11 -> 226824.5 | G13: =G8+G11 -> 231360.99 | H13: =H8+H11 -> 235988.21 | I13: =I8+I11 -> 240707.97 | J13: =J8+J11 -> 245522.13 | ... AF13: =AF8+AF11 -> 379572.23
B14: Annual allowance available after any taper | C14: =MAX(Tax_Bands!C$15,Tax_Bands!C$13-MAX(0,C13-Tax_Bands!C$14)/2) -> 60000 | D14: =MAX(Tax_Bands!D$15,Tax_Bands!D$13-MAX(0,D13-Tax_Bands!D$14)/2) -> 60000 | E14: =MAX(Tax_Bands!E$15,Tax_Bands!E$13-MAX(0,E13-Tax_Bands!E$14)/2) -> 60000 | F14: =MAX(Tax_Bands!F$15,Tax_Bands!F$13-MAX(0,F13-Tax_Bands!F$14)/2) -> 60000 | G14: =MAX(Tax_Bands!G$15,Tax_Bands!G$13-MAX(0,G13-Tax_Bands!G$14)/2) -> 60000 | H14: =MAX(Tax_Bands!H$15,Tax_Bands!H$13-MAX(0,H13-Tax_Bands!H$14)/2) -> 61200 | I14: =MAX(Tax_Bands!I$15,Tax_Bands!I$13-MAX(0,I13-Tax_Bands!I$14)/2) -> 62424 | J14: =MAX(Tax_Bands!J$15,Tax_Bands!J$13-MAX(0,J13-Tax_Bands!J$14)/2) -> 63672.48 | ... AF14: =MAX(Tax_Bands!AF$15,Tax_Bands!AF$13-MAX(0,AF13-Tax_Bands!AF$14)/2) -> 98436.36
B15: SIPP HEADROOM (allowance less workplace contributions) | C15: =MAX(0,MIN(C14-C12,C8-C10)) -> 28800 | D15: =MAX(0,MIN(D14-D12,D8-D10)) -> 27552 | E15: =MAX(0,MIN(E14-E12,E8-E10)) -> 26254.08 | F15: =MAX(0,MIN(F14-F12,F8-F10)) -> 25579.162 | G15: =MAX(0,MIN(G14-G12,G8-G10)) -> 24890.745 | H15: =MAX(0,MIN(H14-H12,H8-H10)) -> 25388.56 | I15: =MAX(0,MIN(I14-I12,I8-I10)) -> 25896.331 | J15: =MAX(0,MIN(J14-J12,J8-J10)) -> 26414.258 | ... AF15: =MAX(0,MIN(AF14-AF12,AF8-AF10)) -> 40835.905
A16: DM — TAX BEFORE ANY PERSONAL SIPP CONTRIBUTION
B17: Taxable pay (income less the employee workplace contribution) | C17: =C8-C10 -> 174400 | D17: =D8-D10 -> 181376 | E17: =E8-E10 -> 188631.04 | F17: =F8-F10 -> 192403.66 | G17: =G8-G10 -> 196251.73 | H17: =H8-H10 -> 200176.77 | I17: =I8-I10 -> 204180.3 | J17: =J8-J10 -> 208263.91 | ... AF17: =AF8-AF10 -> 321971.77
B18: Personal allowance after taper | C18: =MAX(0,Tax_Bands!C$7-MAX(0,C17-Tax_Bands!C$8)/2) -> 0 | D18: =MAX(0,Tax_Bands!D$7-MAX(0,D17-Tax_Bands!D$8)/2) -> 0 | E18: =MAX(0,Tax_Bands!E$7-MAX(0,E17-Tax_Bands!E$8)/2) -> 0 | F18: =MAX(0,Tax_Bands!F$7-MAX(0,F17-Tax_Bands!F$8)/2) -> 0 | G18: =MAX(0,Tax_Bands!G$7-MAX(0,G17-Tax_Bands!G$8)/2) -> 0 | H18: =MAX(0,Tax_Bands!H$7-MAX(0,H17-Tax_Bands!H$8)/2) -> 0 | I18: =MAX(0,Tax_Bands!I$7-MAX(0,I17-Tax_Bands!I$8)/2) -> 0 | J18: =MAX(0,Tax_Bands!J$7-MAX(0,J17-Tax_Bands!J$8)/2) -> 0 | ... AF18: =MAX(0,Tax_Bands!AF$7-MAX(0,AF17-Tax_Bands!AF$8)/2) -> 0
B19: Taxable income | C19: =MAX(0,C17-C18) -> 174400 | D19: =MAX(0,D17-D18) -> 181376 | E19: =MAX(0,E17-E18) -> 188631.04 | F19: =MAX(0,F17-F18) -> 192403.66 | G19: =MAX(0,G17-G18) -> 196251.73 | H19: =MAX(0,H17-H18) -> 200176.77 | I19: =MAX(0,I17-I18) -> 204180.3 | J19: =MAX(0,J17-J18) -> 208263.91 | ... AF19: =MAX(0,AF17-AF18) -> 321971.77
B20: Income tax | C20: =Tax_Bands!C$18*MIN(C19,Tax_Bands!C$9)+Tax_Bands!C$19*MAX(0,MIN(C19,Tax_Bands!C$10)-Tax_Bands!C$9)+Tax_Bands!C$20*MAX(0,C19-Tax_Bands!C$10) -> 64683 | D20: =Tax_Bands!D$18*MIN(D19,Tax_Bands!D$9)+Tax_Bands!D$19*MAX(0,MIN(D19,Tax_Bands!D$10)-Tax_Bands!D$9)+Tax_Bands!D$20*MAX(0,D19-Tax_Bands!D$10) -> 67822.2 | E20: =Tax_Bands!E$18*MIN(E19,Tax_Bands!E$9)+Tax_Bands!E$19*MAX(0,MIN(E19,Tax_Bands!E$10)-Tax_Bands!E$9)+Tax_Bands!E$20*MAX(0,E19-Tax_Bands!E$10) -> 71086.968 | F20: =Tax_Bands!F$18*MIN(F19,Tax_Bands!F$9)+Tax_Bands!F$19*MAX(0,MIN(F19,Tax_Bands!F$10)-Tax_Bands!F$9)+Tax_Bands!F$20*MAX(0,F19-Tax_Bands!F$10) -> 72784.647 | G20: =Tax_Bands!G$18*MIN(G19,Tax_Bands!G$9)+Tax_Bands!G$19*MAX(0,MIN(G19,Tax_Bands!G$10)-Tax_Bands!G$9)+Tax_Bands!G$20*MAX(0,G19-Tax_Bands!G$10) -> 74516.28 | H20: =Tax_Bands!H$18*MIN(H19,Tax_Bands!H$9)+Tax_Bands!H$19*MAX(0,MIN(H19,Tax_Bands!H$10)-Tax_Bands!H$9)+Tax_Bands!H$20*MAX(0,H19-Tax_Bands!H$10) -> 76006.606 | I20: =Tax_Bands!I$18*MIN(I19,Tax_Bands!I$9)+Tax_Bands!I$19*MAX(0,MIN(I19,Tax_Bands!I$10)-Tax_Bands!I$9)+Tax_Bands!I$20*MAX(0,I19-Tax_Bands!I$10) -> 77526.738 | J20: =Tax_Bands!J$18*MIN(J19,Tax_Bands!J$9)+Tax_Bands!J$19*MAX(0,MIN(J19,Tax_Bands!J$10)-Tax_Bands!J$9)+Tax_Bands!J$20*MAX(0,J19-Tax_Bands!J$10) -> 79077.273 | ... AF20: =Tax_Bands!AF$18*MIN(AF19,Tax_Bands!AF$9)+Tax_Bands!AF$19*MAX(0,MIN(AF19,Tax_Bands!AF$10)-Tax_Bands!AF$9)+Tax_Bands!AF$20*MAX(0,AF19-Tax_Bands!AF$10) -> 122251.86
B21: Employee National Insurance | C21: =Tax_Bands!C$21*MAX(0,MIN(C8,Tax_Bands!C$12)-Tax_Bands!C$11)+Tax_Bands!C$22*MAX(0,C8-Tax_Bands!C$12) -> 5810.6 | D21: =Tax_Bands!D$21*MAX(0,MIN(D8,Tax_Bands!D$12)-Tax_Bands!D$11)+Tax_Bands!D$22*MAX(0,D8-Tax_Bands!D$12) -> 5962.6 | E21: =Tax_Bands!E$21*MAX(0,MIN(E8,Tax_Bands!E$12)-Tax_Bands!E$11)+Tax_Bands!E$22*MAX(0,E8-Tax_Bands!E$12) -> 6120.68 | F21: =Tax_Bands!F$21*MAX(0,MIN(F8,Tax_Bands!F$12)-Tax_Bands!F$11)+Tax_Bands!F$22*MAX(0,F8-Tax_Bands!F$12) -> 6202.8816 | G21: =Tax_Bands!G$21*MAX(0,MIN(G8,Tax_Bands!G$12)-Tax_Bands!G$11)+Tax_Bands!G$22*MAX(0,G8-Tax_Bands!G$12) -> 6286.7272 | H21: =Tax_Bands!H$21*MAX(0,MIN(H8,Tax_Bands!H$12)-Tax_Bands!H$11)+Tax_Bands!H$22*MAX(0,H8-Tax_Bands!H$12) -> 6412.4618 | I21: =Tax_Bands!I$21*MAX(0,MIN(I8,Tax_Bands!I$12)-Tax_Bands!I$11)+Tax_Bands!I$22*MAX(0,I8-Tax_Bands!I$12) -> 6540.711 | J21: =Tax_Bands!J$21*MAX(0,MIN(J8,Tax_Bands!J$12)-Tax_Bands!J$11)+Tax_Bands!J$22*MAX(0,J8-Tax_Bands!J$12) -> 6671.5252 | ... AF21: =Tax_Bands!AF$21*MAX(0,MIN(AF8,Tax_Bands!AF$12)-Tax_Bands!AF$11)+Tax_Bands!AF$22*MAX(0,AF8-Tax_Bands!AF$12) -> 10314.042
B22: NET PAY (cash in hand before any personal SIPP contribution) | C22: =C17-C20-C21 -> 103906.4 | D22: =D17-D20-D21 -> 107591.2 | E22: =E17-E20-E21 -> 111423.39 | F22: =F17-F20-F21 -> 113416.13 | G22: =G17-G20-G21 -> 115448.73 | H22: =H17-H20-H21 -> 117757.7 | I22: =I17-I20-I21 -> 120112.86 | J22: =J17-J20-J21 -> 122515.11 | ... AF22: =AF17-AF20-AF21 -> 189405.87
A23: DM — WITH THE PERSONAL SIPP CONTRIBUTION ACTUALLY AFFORDED
B24: Personal SIPP contribution (gross) | C24: =Household_Base!C$38 -> 28800 | D24: =Household_Base!D$38 -> 27552 | E24: =Household_Base!E$38 -> 26254.08 | F24: =Household_Base!F$38 -> 25579.162 | G24: =Household_Base!G$38 -> 24890.745 | H24: =Household_Base!H$38 -> 25388.56 | I24: =Household_Base!I$38 -> 25896.331 | J24: =Household_Base!J$38 -> 26414.258 | ... AF24: =Household_Base!AF$38 -> 40835.905
B25: Adjusted net income | C25: =C17-C24 -> 145600 | D25: =D17-D24 -> 153824 | E25: =E17-E24 -> 162376.96 | F25: =F17-F24 -> 166824.5 | G25: =G17-G24 -> 171360.99 | H25: =H17-H24 -> 174788.21 | I25: =I17-I24 -> 178283.97 | J25: =J17-J24 -> 181849.65 | ... AF25: =AF17-AF24 -> 281135.87
B26: Personal allowance after taper | C26: =MAX(0,Tax_Bands!C$7-MAX(0,C25-Tax_Bands!C$8)/2) -> 0 | D26: =MAX(0,Tax_Bands!D$7-MAX(0,D25-Tax_Bands!D$8)/2) -> 0 | E26: =MAX(0,Tax_Bands!E$7-MAX(0,E25-Tax_Bands!E$8)/2) -> 0 | F26: =MAX(0,Tax_Bands!F$7-MAX(0,F25-Tax_Bands!F$8)/2) -> 0 | G26: =MAX(0,Tax_Bands!G$7-MAX(0,G25-Tax_Bands!G$8)/2) -> 0 | H26: =MAX(0,Tax_Bands!H$7-MAX(0,H25-Tax_Bands!H$8)/2) -> 0 | I26: =MAX(0,Tax_Bands!I$7-MAX(0,I25-Tax_Bands!I$8)/2) -> 0 | J26: =MAX(0,Tax_Bands!J$7-MAX(0,J25-Tax_Bands!J$8)/2) -> 0 | ... AF26: =MAX(0,Tax_Bands!AF$7-MAX(0,AF25-Tax_Bands!AF$8)/2) -> 0
B27: Taxable income | C27: =MAX(0,C17-C26) -> 174400 | D27: =MAX(0,D17-D26) -> 181376 | E27: =MAX(0,E17-E26) -> 188631.04 | F27: =MAX(0,F17-F26) -> 192403.66 | G27: =MAX(0,G17-G26) -> 196251.73 | H27: =MAX(0,H17-H26) -> 200176.77 | I27: =MAX(0,I17-I26) -> 204180.3 | J27: =MAX(0,J17-J26) -> 208263.91 | ... AF27: =MAX(0,AF17-AF26) -> 321971.77
